import asyncio
import traceback


async def handle_aio_exceptions(fn, *args, **kwargs):
    try:
        await fn(*args, **kwargs)
    except asyncio.CancelledError:
        pass
    except Exception:
        traceback.print_exc()
